<?xml version="1.0"?>
<robot name="line_follower">

	<link name="chassis">
		<visual>
			<origin xyz="0 0 0.0415" rpy="0 0 0"/>
			<geometry>
				<box size="0.15 0.08 0.003"/>
			</geometry>
			<material name="white">
				<color rgba="1 1 1 1"/>
			</material>
		</visual>
		<collision>
			<origin xyz="0 0 0.0415" rpy="0 0 0"/>
			<geometry>
				<box size="0.15 0.08 0.003"/>
			</geometry>
		</collision>
		<inertial>
			<origin xyz="0 0 0.0415" rpy="0 0 0"/>
			<mass value="0.03744"/>
			<inertia ixx="0.0000200" ixy="0" ixz="0" iyy="0.0000312" iyz="0" izz="0.0000512"/>
		</inertial>
	</link>

	<link name="left_wheel">
		<visual>
			<origin xyz="0 0 0" rpy="1.5708 0 0"/>
			<geometry>
				<cylinder radius="0.04" length="0.03"/>
			</geometry>
			<material name="black">
				<color rgba="0 0 0 1"/>
			</material>
		</visual>
		<collision>
			<origin xyz="0 0 0" rpy="1.5708 0 0"/>
			<geometry>
				<cylinder radius="0.04" length="0.03"/>
			</geometry>
		</collision>
		<inertial>
			<origin xyz="0 0 0"/>
			<mass value="0.215"/>
			<inertia ixx="0.000108" ixy="0" ixz="0" iyy="0.000108" iyz="0" izz="0.000172"/>
		</inertial>
	</link>

 
	<link name="right_wheel">
		<visual>
			<origin xyz="0 0 0" rpy="1.5708 0 0"/>
			<geometry>
				<cylinder radius="0.04" length="0.03"/>
			</geometry>
			<material name="black">
				<color rgba="0 0 0 1"/>
			</material>
		</visual>
		<collision>
			<origin xyz="0 0 0" rpy="1.5708 0 0"/>
			<geometry>
				<cylinder radius="0.04" length="0.03"/>
			</geometry>
		</collision>
		<inertial>
			<origin xyz="0 0 0"/>
			<mass value="0.215"/>
			<inertia ixx="0.000108" ixy="0" ixz="0" iyy="0.000108" iyz="0" izz="0.000172"/>
		</inertial>
	</link>
	<link name="center_housing">
		  <visual>
				<geometry>
				  	<cylinder radius="0.025" length="0.02"/>
				</geometry>
				<material name="red">
					<color rgba="1 0 0 1"/>
				</material>
		  </visual>
	</link>

	<link name="center_wheel">
		<visual>
			<origin xyz="0 0 0" rpy="0 0 0"/>
			<geometry>
				<sphere radius="0.02"/>
			</geometry>
			<material name="stainless">
  				<color rgba="0.85 0.85 0.88 1"/>
			</material>
		</visual>
		<collision>
			<origin xyz="0 0 0" rpy="0 0 0"/>
			<geometry>
				<sphere radius="0.02"/>
			</geometry>
		</collision>
		<inertial>
			<origin xyz="0 0 0"/>
			<mass value="0.05"/>
			<inertia ixx="0.00001" ixy="0" ixz="0" iyy="0.00001" iyz="0" izz="0.00001"/>
		</inertial>
	</link>

	<joint name="left_wheel_joint" type="continuous">
		<parent link="chassis"/>
		<child link="left_wheel"/>
		<origin xyz="-0.05 0.0575 0.04" rpy="0 0 0"/>
		<axis xyz="0 1 0"/>
	</joint>

	
	<joint name="right_wheel_joint" type="continuous">
		<parent link="chassis"/>
		<child link="right_wheel"/>
		<origin xyz="-0.05 -0.0575 0.04" rpy="0 0 0"/>
		<axis xyz="0 1 0"/>
	</joint>

	<joint name="housing_joint" type="fixed">
		  <parent link="chassis"/>
		  <child link="center_housing"/>
		  <origin xyz="0.05 0 0.03"/>
	</joint>
	<joint name="center_wheel_joint" type="fixed">
		<parent link="center_housing"/>
		<child link="center_wheel"/>
		<origin xyz="0.00 0 -0.01" rpy="0 0 0"/>
	</joint>
  
  
	<gazebo>
		<plugin  filename="gz-sim-diff-drive-system" name="gz::sim::systems::DiffDrive">
			<left_joint>left_wheel_joint</left_joint>
			<right_joint>right_wheel_joint</right_joint>
			<wheel_separation>0.115</wheel_separation>
			<wheel_radius>0.04</wheel_radius>
			<topic>cmd_vel</topic>
			<odom_topic>odom</odom_topic>
			<frame_id>odom</frame_id>
			<child_frame_id>chassis</child_frame_id>
		</plugin>
			<sensor name="imu_sensor" type="imu">
			<always_on>1</always_on>
			<update_rate>1</update_rate>
			<visualize>true</visualize>
			<topic>imu</topic>
			</sensor>
	</gazebo>


</robot>
